<?xml version="1.0" ?>
<!-- =================================================================================== -->
<!-- |    This document was autogenerated by xacro from panther.urdf.xacro             | -->
<!-- |    EDITING THIS FILE BY HAND IS NOT RECOMMENDED                                 | -->
<!-- =================================================================================== -->
<robot name="panther">
  <link name="base_link"/>
  <joint name="base_to_body_joint" type="fixed">
    <origin rpy="0.0 0.0 0.0" xyz="0.0 0.0 0.1825"/>
    <parent link="base_link"/>
    <child link="body_link"/>
  </joint>
  <link name="body_link">
    <visual>
      <origin rpy="0.0 0.0 0.0" xyz="0.0 0.0 0.0"/>
      <geometry>
        <mesh filename="http://{{.Host}}:{{env "FOXGLOVE_PORT"}}/ros2_ws/install/panther_description/share/panther_description/meshes/body.dae"/>
      </geometry>
    </visual>
    <collision>
      <origin rpy="0.0 0.0 0.0" xyz="0.0 0.0 0.0"/>
      <geometry>
        <mesh filename="http://{{.Host}}:{{env "FOXGLOVE_PORT"}}/ros2_ws/install/panther_description/share/panther_description/meshes/body_collision.stl"/>
      </geometry>
    </collision>
    <inertial>
      <origin rpy="0.0 0.0 0.0" xyz="0.0 0.0 0.0"/>
      <mass value="43.0"/>
      <inertia ixx="2.630036" ixy="-0.023480" ixz="0.052320" iyy="2.463509" iyz="0.009337" izz="4.611945"/>
    </inertial>
  </link>
  <joint name="body_to_imu_joint" type="fixed">
    <origin rpy="0.0 0.0 -1.57" xyz="0.169 0.025 0.092"/>
    <parent link="body_link"/>
    <child link="imu_link"/>
  </joint>
  <link name="imu_link"/>
  <joint name="body_to_front_light_joint" type="fixed">
    <origin rpy="0.0 0.0 0.0" xyz="0.362 0.0 0.0"/>
    <parent link="body_link"/>
    <child link="front_light_link"/>
  </joint>
  <link name="front_light_link"/>
  <joint name="body_to_rear_light_joint" type="fixed">
    <origin rpy="0.0 0.0 3.141592653589793" xyz="-0.362 0.0 0.0"/>
    <parent link="body_link"/>
    <child link="rear_light_link"/>
  </joint>
  <link name="rear_light_link"/>
  <joint name="body_to_cover_joint" type="fixed">
    <origin rpy="0.0 0.0 0.0" xyz="0.0 0.0 0.1715"/>
    <parent link="body_link"/>
    <child link="cover_link"/>
  </joint>
  <link name="cover_link"/>
  <joint name="fl_wheel_joint" type="continuous">
    <origin rpy="0.0 0.0 0.0" xyz="0.22 0.3485 0.0"/>
    <parent link="body_link"/>
    <child link="fl_wheel_link"/>
    <axis xyz="0.0 1.0 0.0"/>
    <limit effort="34.5" velocity="2.0"/>
    <dynamics damping="0.01" friction="0.01"/>
  </joint>
  <link name="fl_wheel_link">
    <visual>
      <origin rpy="0.0 0.0 0.0" xyz="0.0 0.0 0.0"/>
      <geometry>
        <mesh filename="http://{{.Host}}:{{env "FOXGLOVE_PORT"}}/ros2_ws/install/panther_description/share/panther_description/meshes/WH01/fl_wheel.dae"/>
      </geometry>
    </visual>
    <collision>
      <origin rpy="0.0 0.0 0.0" xyz="0.0 0.0 0.0"/>
      <geometry>
        <mesh filename="http://{{.Host}}:{{env "FOXGLOVE_PORT"}}/ros2_ws/install/panther_description/share/panther_description/meshes/WH01/wheel_collision.stl"/>
      </geometry>
    </collision>
    <inertial>
      <origin rpy="0.0 0.0 0.0" xyz="0.0 0.0 0.0"/>
      <mass value="3.0"/>
      <inertia ixx="0.02251" ixy="0.0" ixz="0.0" iyy="0.03485" iyz="0.0" izz="0.02251"/>
    </inertial>
  </link>
  <joint name="fr_wheel_joint" type="continuous">
    <origin rpy="0.0 0.0 0.0" xyz="0.22 -0.3485 0.0"/>
    <parent link="body_link"/>
    <child link="fr_wheel_link"/>
    <axis xyz="0.0 1.0 0.0"/>
    <limit effort="34.5" velocity="2.0"/>
    <dynamics damping="0.01" friction="0.01"/>
  </joint>
  <link name="fr_wheel_link">
    <visual>
      <origin rpy="0.0 0.0 0.0" xyz="0.0 0.0 0.0"/>
      <geometry>
        <mesh filename="http://{{.Host}}:{{env "FOXGLOVE_PORT"}}/ros2_ws/install/panther_description/share/panther_description/meshes/WH01/fr_wheel.dae"/>
      </geometry>
    </visual>
    <collision>
      <origin rpy="0.0 0.0 0.0" xyz="0.0 0.0 0.0"/>
      <geometry>
        <mesh filename="http://{{.Host}}:{{env "FOXGLOVE_PORT"}}/ros2_ws/install/panther_description/share/panther_description/meshes/WH01/wheel_collision.stl"/>
      </geometry>
    </collision>
    <inertial>
      <origin rpy="0.0 0.0 0.0" xyz="0.0 -0.0 0.0"/>
      <mass value="3.0"/>
      <inertia ixx="0.02251" ixy="0.0" ixz="0.0" iyy="0.03485" iyz="0.0" izz="0.02251"/>
    </inertial>
  </link>
  <joint name="rl_wheel_joint" type="continuous">
    <origin rpy="0.0 0.0 0.0" xyz="-0.22 0.3485 0.0"/>
    <parent link="body_link"/>
    <child link="rl_wheel_link"/>
    <axis xyz="0.0 1.0 0.0"/>
    <limit effort="34.5" velocity="2.0"/>
    <dynamics damping="0.01" friction="0.01"/>
  </joint>
  <link name="rl_wheel_link">
    <visual>
      <origin rpy="0.0 0.0 0.0" xyz="0.0 0.0 0.0"/>
      <geometry>
        <mesh filename="http://{{.Host}}:{{env "FOXGLOVE_PORT"}}/ros2_ws/install/panther_description/share/panther_description/meshes/WH01/rl_wheel.dae"/>
      </geometry>
    </visual>
    <collision>
      <origin rpy="0.0 0.0 0.0" xyz="0.0 0.0 0.0"/>
      <geometry>
        <mesh filename="http://{{.Host}}:{{env "FOXGLOVE_PORT"}}/ros2_ws/install/panther_description/share/panther_description/meshes/WH01/wheel_collision.stl"/>
      </geometry>
    </collision>
    <inertial>
      <origin rpy="0.0 0.0 0.0" xyz="0.0 0.0 0.0"/>
      <mass value="3.0"/>
      <inertia ixx="0.02251" ixy="0.0" ixz="0.0" iyy="0.03485" iyz="0.0" izz="0.02251"/>
    </inertial>
  </link>
  <joint name="rr_wheel_joint" type="continuous">
    <origin rpy="0.0 0.0 0.0" xyz="-0.22 -0.3485 0.0"/>
    <parent link="body_link"/>
    <child link="rr_wheel_link"/>
    <axis xyz="0.0 1.0 0.0"/>
    <limit effort="34.5" velocity="2.0"/>
    <dynamics damping="0.01" friction="0.01"/>
  </joint>
  <link name="rr_wheel_link">
    <visual>
      <origin rpy="0.0 0.0 0.0" xyz="0.0 0.0 0.0"/>
      <geometry>
        <mesh filename="http://{{.Host}}:{{env "FOXGLOVE_PORT"}}/ros2_ws/install/panther_description/share/panther_description/meshes/WH01/rr_wheel.dae"/>
      </geometry>
    </visual>
    <collision>
      <origin rpy="0.0 0.0 0.0" xyz="0.0 0.0 0.0"/>
      <geometry>
        <mesh filename="http://{{.Host}}:{{env "FOXGLOVE_PORT"}}/ros2_ws/install/panther_description/share/panther_description/meshes/WH01/wheel_collision.stl"/>
      </geometry>
    </collision>
    <inertial>
      <origin rpy="0.0 0.0 0.0" xyz="0.0 -0.0 0.0"/>
      <mass value="3.0"/>
      <inertia ixx="0.02251" ixy="0.0" ixz="0.0" iyy="0.03485" iyz="0.0" izz="0.02251"/>
    </inertial>
  </link>
  <ros2_control name="wheels" type="system">
    <hardware>
      <plugin>panther_hardware_interfaces/PantherSystem</plugin>
      <param name="encoder_resolution">1600</param>
      <param name="gear_ratio">30.08</param>
      <param name="gearbox_efficiency">0.75</param>
      <!-- Same as set in the Roboteq driver (TNM parameter) -->
      <param name="motor_torque_constant">0.11</param>
      <!-- Max RPM speed set in the Roboteq driver (MXRPM parameter) -->
      <param name="max_rpm_motor_speed">3600.0</param>
      <param name="master_can_id">3</param>
      <param name="front_driver_can_id">1</param>
      <param name="rear_driver_can_id">2</param>
    </hardware>
    <joint name="fl_wheel_joint">
      <command_interface name="velocity"/>
      <state_interface name="position"/>
      <state_interface name="velocity"/>
      <state_interface name="effort"/>
    </joint>
    <joint name="fr_wheel_joint">
      <command_interface name="velocity"/>
      <state_interface name="position"/>
      <state_interface name="velocity"/>
      <state_interface name="effort"/>
    </joint>
    <joint name="rl_wheel_joint">
      <command_interface name="velocity"/>
      <state_interface name="position"/>
      <state_interface name="velocity"/>
      <state_interface name="effort"/>
    </joint>
    <joint name="rr_wheel_joint">
      <command_interface name="velocity"/>
      <state_interface name="position"/>
      <state_interface name="velocity"/>
      <state_interface name="effort"/>
    </joint>
  </ros2_control>
  <joint name="cover_to_ouster_os1_32_joint" type="fixed">
    <origin rpy="0.0 0.0 0.0" xyz="0.135 0.0 0.0"/>
    <parent link="cover_link"/>
    <child link="ouster_os1_32_link"/>
  </joint>
  <link name="ouster_os1_32_link">
    <visual>
      <origin rpy="0.0 0.0 0.0" xyz="0.0 0.0 0.0"/>
      <geometry>
        <mesh filename="http://{{.Host}}:{{env "FOXGLOVE_PORT"}}/ros2_ws/install/ros_components_description/share/ros_components_description/meshes/ouster_os1_32.dae"/>
      </geometry>
    </visual>
    <collision>
      <origin rpy="0.0 0.0 0.0" xyz="0.0 0.0 0.036"/>
      <geometry>
        <cylinder length="0.073" radius="0.0425"/>
      </geometry>
    </collision>
    <inertial>
      <origin rpy="0.0 0.0 0.0" xyz="0.0 0.0 0.036"/>
      <mass value="0.447"/>
      <inertia ixx="0.00047706" ixy="0.0" ixz="0.0" iyy="0.00047706" iyz="0.0" izz="0.00053722"/>
    </inertial>
  </link>
  <joint name="ouster_os1_32_to_os_lidar_joint" type="fixed">
    <origin rpy="0.0 0.0 0.0" xyz="0.0 0.0 0.03618"/>
    <parent link="ouster_os1_32_link"/>
    <child link="os_lidar"/>
  </joint>
  <link name="os_lidar"/>
  <gazebo reference="os_lidar">
    <sensor name="ouster_os1_32_sensor" type="ray">
      <visualize>false</visualize>
      <ray>
        <scan>
          <horizontal>
            <samples>1024</samples>
            <resolution>1</resolution>
            <min_angle>-3.141592653589793</min_angle>
            <max_angle>3.141592653589793</max_angle>
          </horizontal>
          <vertical>
            <samples>32</samples>
            <resolution>1</resolution>
            <min_angle>-0.39269908169872414</min_angle>
            <max_angle>0.39269908169872414</max_angle>
          </vertical>
        </scan>
        <range>
          <min>0.8</min>
          <max>120.0</max>
          <resolution>0.003</resolution>
        </range>
        <noise>
          <type>gaussian</type>
          <mean>0.0</mean>
          <stddev>0.0008</stddev>
        </noise>
      </ray>
      <update_rate>20.0</update_rate>
      <plugin filename="libgazebo_ros_ray_sensor.so" name="ouster_os1_32_ray">
        <ros>
          <namespace/>
          <remapping>~/out:=os_lidar</remapping>
        </ros>
        <output_type>sensor_msgs/PointCloud2</output_type>
        <frame_name>os_lidar</frame_name>
      </plugin>
    </sensor>
  </gazebo>
</robot>
